2023-08-17 11:33:33,858 ERROR Internal Server Error: /news/ C:\Users\Администратор\AppData\Local\Programs\Python\Python311\Lib\site-packages\django\utils\log.py (<class 'django.template.exceptions.TemplateDoesNotExist'>, TemplateDoesNotExist('news/post_list.html'), <traceback object at 0x0000012582362980>)
Traceback (most recent call last):
  File "C:\Users\Администратор\AppData\Local\Programs\Python\Python311\Lib\site-packages\django\core\handlers\exception.py", line 55, in inner
    response = get_response(request)
               ^^^^^^^^^^^^^^^^^^^^^
  File "C:\Users\Администратор\AppData\Local\Programs\Python\Python311\Lib\site-packages\django\core\handlers\base.py", line 220, in _get_response
    response = response.render()
               ^^^^^^^^^^^^^^^^^
  File "C:\Users\Администратор\AppData\Local\Programs\Python\Python311\Lib\site-packages\django\template\response.py", line 111, in render
    self.content = self.rendered_content
                   ^^^^^^^^^^^^^^^^^^^^^
  File "C:\Users\Администратор\AppData\Local\Programs\Python\Python311\Lib\site-packages\django\template\response.py", line 87, in rendered_content
    template = self.resolve_template(self.template_name)
               ^^^^^^^^^^^^^^^^^^^^^^^^^^^^^^^^^^^^^^^^^
  File "C:\Users\Администратор\AppData\Local\Programs\Python\Python311\Lib\site-packages\django\template\response.py", line 69, in resolve_template
    return select_template(template, using=self.using)
           ^^^^^^^^^^^^^^^^^^^^^^^^^^^^^^^^^^^^^^^^^^^
  File "C:\Users\Администратор\AppData\Local\Programs\Python\Python311\Lib\site-packages\django\template\loader.py", line 47, in select_template
    raise TemplateDoesNotExist(", ".join(template_name_list), chain=chain)
django.template.exceptions.TemplateDoesNotExist: news/post_list.html
2023-08-17 11:33:33,858 ERROR "GET /news/ HTTP/1.1" 500 92758 C:\Users\Администратор\AppData\Local\Programs\Python\Python311\Lib\site-packages\django\core\servers\basehttp.py None
